Workbook

Sheet 📊 ダッシュボード
A1: 📊 研修進捗ダッシュボード 第2弾：初成約〜1ヶ月
A2: ="最終更新： "&TEXT(TODAY(),"YYYY年 MM月 DD日")
A4: No. | B4: メンバー名 | C4: 開始日 | D4: 全体進捗 | E4: 進捗バー | F4: ✅ 合格 | G4: 🔄 練習中 | H4: 🔴 遅れ | I4: ⬜ 未着手 | J4: 経過日数 | K4: 残りアイテム
A5: 1 | B5: ='メンバー1'!B2 | C5: ='メンバー1'!D2 | D5: ='メンバー1'!F2 | E5: =REPT("█",INT('メンバー1'!F2*20))&REPT("░",20-INT('メンバー1'!F2*20))&" "&TEXT('メンバー1'!F2,"0%") | F5: =COUNTIF('メンバー1'!G6:G55,"*合格*") | G5: =COUNTIF('メンバー1'!G6:G55,"*練習中*") | H5: =COUNTIF('メンバー1'!G6:G55,"*遅れ*") | I5: =COUNTIF('メンバー1'!G6:G55,"*未着手*") | J5: ='メンバー1'!H2 | K5: =30-F5
A6: 2 | B6: ='メンバー2'!B2 | C6: ='メンバー2'!D2 | D6: ='メンバー2'!F2 | E6: =REPT("█",INT('メンバー2'!F2*20))&REPT("░",20-INT('メンバー2'!F2*20))&" "&TEXT('メンバー2'!F2,"0%") | F6: =COUNTIF('メンバー2'!G6:G55,"*合格*") | G6: =COUNTIF('メンバー2'!G6:G55,"*練習中*") | H6: =COUNTIF('メンバー2'!G6:G55,"*遅れ*") | I6: =COUNTIF('メンバー2'!G6:G55,"*未着手*") | J6: ='メンバー2'!H2 | K6: =30-F6
A7: 3 | B7: ='メンバー3'!B2 | C7: ='メンバー3'!D2 | D7: ='メンバー3'!F2 | E7: =REPT("█",INT('メンバー3'!F2*20))&REPT("░",20-INT('メンバー3'!F2*20))&" "&TEXT('メンバー3'!F2,"0%") | F7: =COUNTIF('メンバー3'!G6:G55,"*合格*") | G7: =COUNTIF('メンバー3'!G6:G55,"*練習中*") | H7: =COUNTIF('メンバー3'!G6:G55,"*遅れ*") | I7: =COUNTIF('メンバー3'!G6:G55,"*未着手*") | J7: ='メンバー3'!H2 | K7: =30-F7

Sheet メンバー1
A1: 🎓 第2弾：初成約〜1ヶ月 トレーニングシート
A2: 👤 メンバー名 | B2: メンバー1 | C2: 📅 開始日 | E2: 📊 全体進捗 | F2: =AVERAGE(F8:F12,F16:F26,F30:F34,F38:F45,F49) | G2: ⏱ 経過日数 | H2: =IF(D2="","",TODAY()-D2) | I2: 日
A3: =REPT("█",INT(F2*30))&REPT("░",30-INT(F2*30))&" "&TEXT(F2,"0%")&" 完了"
A5: ✔ | B5: トレーニング項目 | C5: 目標日 | D5: RP目標 | E5: RP実績 | F5: 達成率 | G5: ステータス | H5: 進捗バー | I5: メモ
A6: 🎯 アポの解像度を上げるトレーニング
B7: 項目名 | C7: 目標日 | D7: RP目標 | E7: RP実績 | F7: 達成率 | G7: ステータス | H7: 進捗バー | I7: メモ
A8: □ | B8: アイスブレイク | D8: 5 | E8: 0 | F8: =IF(D8=0,0,MIN(E8/D8,1)) | G8: =IF(AND(E8>=D8,D8>0),"✅ 合格",IF(E8>0,"🔄 練習中",IF(AND(C8<>"",C8<TODAY()),"🔴 遅れ","⬜ 未着手"))) | H8: =REPT("█",INT(F8*10))&REPT("░",10-INT(F8*10))&" "&TEXT(F8,"0%")
A9: □ | B9: ヒアリング | D9: 5 | E9: 0 | F9: =IF(D9=0,0,MIN(E9/D9,1)) | G9: =IF(AND(E9>=D9,D9>0),"✅ 合格",IF(E9>0,"🔄 練習中",IF(AND(C9<>"",C9<TODAY()),"🔴 遅れ","⬜ 未着手"))) | H9: =REPT("█",INT(F9*10))&REPT("░",10-INT(F9*10))&" "&TEXT(F9,"0%")
A10: □ | B10: ストーリー | D10: 5 | E10: 0 | F10: =IF(D10=0,0,MIN(E10/D10,1)) | G10: =IF(AND(E10>=D10,D10>0),"✅ 合格",IF(E10>0,"🔄 練習中",IF(AND(C10<>"",C10<TODAY()),"🔴 遅れ","⬜ 未着手"))) | H10: =REPT("█",INT(F10*10))&REPT("░",10-INT(F10*10))&" "&TEXT(F10,"0%")
A11: □ | B11: 提案資料 | D11: 3 | E11: 0 | F11: =IF(D11=0,0,MIN(E11/D11,1)) | G11: =IF(AND(E11>=D11,D11>0),"✅ 合格",IF(E11>0,"🔄 練習中",IF(AND(C11<>"",C11<TODAY()),"🔴 遅れ","⬜ 未着手"))) | H11: =REPT("█",INT(F11*10))&REPT("░",10-INT(F11*10))&" "&TEXT(F11,"0%")
A12: □ | B12: ブリッジ | D12: 5 | E12: 0 | F12: =IF(D12=0,0,MIN(E12/D12,1)) | G12: =IF(AND(E12>=D12,D12>0),"✅ 合格",IF(E12>0,"🔄 練習中",IF(AND(C12<>"",C12<TODAY()),"🔴 遅れ","⬜ 未着手"))) | H12: =REPT("█",INT(F12*10))&REPT("░",10-INT(F12*10))&" "&TEXT(F12,"0%")
A14: 🎤 プレの解像度を上げるトレーニング
B15: 項目名 | C15: 目標日 | D15: RP目標 | E15: RP実績 | F15: 達成率 | G15: ステータス | H15: 進捗バー | I15: メモ
A16: □ | B16: 再アイスブレイク | D16: 5 | E16: 0 | F16: =IF(D16=0,0,MIN(E16/D16,1)) | G16: =IF(AND(E16>=D16,D16>0),"✅ 合格",IF(E16>0,"🔄 練習中",IF(AND(C16<>"",C16<TODAY()),"🔴 遅れ","⬜ 未着手"))) | H16: =REPT("█",INT(F16*10))&REPT("░",10-INT(F16*10))&" "&TEXT(F16,"0%")
A17: □ | B17: 再ヒアリング | D17: 5 | E17: 0 | F17: =IF(D17=0,0,MIN(E17/D17,1)) | G17: =IF(AND(E17>=D17,D17>0),"✅ 合格",IF(E17>0,"🔄 練習中",IF(AND(C17<>"",C17<TODAY()),"🔴 遅れ","⬜ 未着手"))) | H17: =REPT("█",INT(F17*10))&REPT("░",10-INT(F17*10))&" "&TEXT(F17,"0%")
A18: □ | B18: 前回の振り返り | D18: 3 | E18: 0 | F18: =IF(D18=0,0,MIN(E18/D18,1)) | G18: =IF(AND(E18>=D18,D18>0),"✅ 合格",IF(E18>0,"🔄 練習中",IF(AND(C18<>"",C18<TODAY()),"🔴 遅れ","⬜ 未着手"))) | H18: =REPT("█",INT(F18*10))&REPT("░",10-INT(F18*10))&" "&TEXT(F18,"0%")
A19: □ | B19: 不安ヒアリング・検討潰し | D19: 8 | E19: 0 | F19: =IF(D19=0,0,MIN(E19/D19,1)) | G19: =IF(AND(E19>=D19,D19>0),"✅ 合格",IF(E19>0,"🔄 練習中",IF(AND(C19<>"",C19<TODAY()),"🔴 遅れ","⬜ 未着手"))) | H19: =REPT("█",INT(F19*10))&REPT("░",10-INT(F19*10))&" "&TEXT(F19,"0%")
A20: □ | B20: サポート説明 | D20: 5 | E20: 0 | F20: =IF(D20=0,0,MIN(E20/D20,1)) | G20: =IF(AND(E20>=D20,D20>0),"✅ 合格",IF(E20>0,"🔄 練習中",IF(AND(C20<>"",C20<TODAY()),"🔴 遅れ","⬜ 未着手"))) | H20: =REPT("█",INT(F20*10))&REPT("░",10-INT(F20*10))&" "&TEXT(F20,"0%")
A21: □ | B21: 卒業生の話 | D21: 5 | E21: 0 | F21: =IF(D21=0,0,MIN(E21/D21,1)) | G21: =IF(AND(E21>=D21,D21>0),"✅ 合格",IF(E21>0,"🔄 練習中",IF(AND(C21<>"",C21<TODAY()),"🔴 遅れ","⬜ 未着手"))) | H21: =REPT("█",INT(F21*10))&REPT("░",10-INT(F21*10))&" "&TEXT(F21,"0%")
A22: □ | B22: アンカリング | D22: 5 | E22: 0 | F22: =IF(D22=0,0,MIN(E22/D22,1)) | G22: =IF(AND(E22>=D22,D22>0),"✅ 合格",IF(E22>0,"🔄 練習中",IF(AND(C22<>"",C22<TODAY()),"🔴 遅れ","⬜ 未着手"))) | H22: =REPT("█",INT(F22*10))&REPT("░",10-INT(F22*10))&" "&TEXT(F22,"0%")
A23: □ | B23: 金額オファー | D23: 8 | E23: 0 | F23: =IF(D23=0,0,MIN(E23/D23,1)) | G23: =IF(AND(E23>=D23,D23>0),"✅ 合格",IF(E23>0,"🔄 練習中",IF(AND(C23<>"",C23<TODAY()),"🔴 遅れ","⬜ 未着手"))) | H23: =REPT("█",INT(F23*10))&REPT("░",10-INT(F23*10))&" "&TEXT(F23,"0%")
A24: □ | B24: 言質後トーク | D24: 5 | E24: 0 | F24: =IF(D24=0,0,MIN(E24/D24,1)) | G24: =IF(AND(E24>=D24,D24>0),"✅ 合格",IF(E24>0,"🔄 練習中",IF(AND(C24<>"",C24<TODAY()),"🔴 遅れ","⬜ 未着手"))) | H24: =REPT("█",INT(F24*10))&REPT("░",10-INT(F24*10))&" "&TEXT(F24,"0%")
A25: □ | B25: 切り返し | D25: 10 | E25: 0 | F25: =IF(D25=0,0,MIN(E25/D25,1)) | G25: =IF(AND(E25>=D25,D25>0),"✅ 合格",IF(E25>0,"🔄 練習中",IF(AND(C25<>"",C25<TODAY()),"🔴 遅れ","⬜ 未着手"))) | H25: =REPT("█",INT(F25*10))&REPT("░",10-INT(F25*10))&" "&TEXT(F25,"0%")
A26: □ | B26: ボイチェン提案 | D26: 5 | E26: 0 | F26: =IF(D26=0,0,MIN(E26/D26,1)) | G26: =IF(AND(E26>=D26,D26>0),"✅ 合格",IF(E26>0,"🔄 練習中",IF(AND(C26<>"",C26<TODAY()),"🔴 遅れ","⬜ 未着手"))) | H26: =REPT("█",INT(F26*10))&REPT("░",10-INT(F26*10))&" "&TEXT(F26,"0%")
A28: 💬 渋りトーク
B29: 項目名 | C29: 目標日 | D29: RP目標 | E29: RP実績 | F29: 達成率 | G29: ステータス | H29: 進捗バー | I29: メモ
A30: □ | B30: 金額渋りトーク | D30: 8 | E30: 0 | F30: =IF(D30=0,0,MIN(E30/D30,1)) | G30: =IF(AND(E30>=D30,D30>0),"✅ 合格",IF(E30>0,"🔄 練習中",IF(AND(C30<>"",C30<TODAY()),"🔴 遅れ","⬜ 未着手"))) | H30: =REPT("█",INT(F30*10))&REPT("░",10-INT(F30*10))&" "&TEXT(F30,"0%")
A31: □ | B31: 相談渋りのトーク | D31: 8 | E31: 0 | F31: =IF(D31=0,0,MIN(E31/D31,1)) | G31: =IF(AND(E31>=D31,D31>0),"✅ 合格",IF(E31>0,"🔄 練習中",IF(AND(C31<>"",C31<TODAY()),"🔴 遅れ","⬜ 未着手"))) | H31: =REPT("█",INT(F31*10))&REPT("░",10-INT(F31*10))&" "&TEXT(F31,"0%")
A32: □ | B32: 他社比較渋りトーク | D32: 5 | E32: 0 | F32: =IF(D32=0,0,MIN(E32/D32,1)) | G32: =IF(AND(E32>=D32,D32>0),"✅ 合格",IF(E32>0,"🔄 練習中",IF(AND(C32<>"",C32<TODAY()),"🔴 遅れ","⬜ 未着手"))) | H32: =REPT("█",INT(F32*10))&REPT("░",10-INT(F32*10))&" "&TEXT(F32,"0%")
A33: □ | B33: 自信ない渋りトーク | D33: 5 | E33: 0 | F33: =IF(D33=0,0,MIN(E33/D33,1)) | G33: =IF(AND(E33>=D33,D33>0),"✅ 合格",IF(E33>0,"🔄 練習中",IF(AND(C33<>"",C33<TODAY()),"🔴 遅れ","⬜ 未着手"))) | H33: =REPT("█",INT(F33*10))&REPT("░",10-INT(F33*10))&" "&TEXT(F33,"0%")
A34: □ | B34: 今じゃない渋りトーク | D34: 5 | E34: 0 | F34: =IF(D34=0,0,MIN(E34/D34,1)) | G34: =IF(AND(E34>=D34,D34>0),"✅ 合格",IF(E34>0,"🔄 練習中",IF(AND(C34<>"",C34<TODAY()),"🔴 遅れ","⬜ 未着手"))) | H34: =REPT("█",INT(F34*10))&REPT("░",10-INT(F34*10))&" "&TEXT(F34,"0%")
A36: ⚡ スキル強化
B37: 項目名 | C37: 目標日 | D37: RP目標 | E37: RP実績 | F37: 達成率 | G37: ステータス | H37: 進捗バー | I37: メモ
A38: □ | B38: アポやプレでの時間配分の徹底 | D38: 3 | E38: 0 | F38: =IF(D38=0,0,MIN(E38/D38,1)) | G38: =IF(AND(E38>=D38,D38>0),"✅ 合格",IF(E38>0,"🔄 練習中",IF(AND(C38<>"",C38<TODAY()),"🔴 遅れ","⬜ 未着手"))) | H38: =REPT("█",INT(F38*10))&REPT("░",10-INT(F38*10))&" "&TEXT(F38,"0%")
A39: □ | B39: ボイチェン提案 | D39: 3 | E39: 0 | F39: =IF(D39=0,0,MIN(E39/D39,1)) | G39: =IF(AND(E39>=D39,D39>0),"✅ 合格",IF(E39>0,"🔄 練習中",IF(AND(C39<>"",C39<TODAY()),"🔴 遅れ","⬜ 未着手"))) | H39: =REPT("█",INT(F39*10))&REPT("░",10-INT(F39*10))&" "&TEXT(F39,"0%")
A40: □ | B40: 不安ヒアリング | D40: 5 | E40: 0 | F40: =IF(D40=0,0,MIN(E40/D40,1)) | G40: =IF(AND(E40>=D40,D40>0),"✅ 合格",IF(E40>0,"🔄 練習中",IF(AND(C40<>"",C40<TODAY()),"🔴 遅れ","⬜ 未着手"))) | H40: =REPT("█",INT(F40*10))&REPT("░",10-INT(F40*10))&" "&TEXT(F40,"0%")
A41: □ | B41: 資金繰りの解像度UP（カードの分割・最低限の金融リテラシー） | D41: 3 | E41: 0 | F41: =IF(D41=0,0,MIN(E41/D41,1)) | G41: =IF(AND(E41>=D41,D41>0),"✅ 合格",IF(E41>0,"🔄 練習中",IF(AND(C41<>"",C41<TODAY()),"🔴 遅れ","⬜ 未着手"))) | H41: =REPT("█",INT(F41*10))&REPT("░",10-INT(F41*10))&" "&TEXT(F41,"0%")
A42: □ | B42: 事実解釈の区別 | D42: 3 | E42: 0 | F42: =IF(D42=0,0,MIN(E42/D42,1)) | G42: =IF(AND(E42>=D42,D42>0),"✅ 合格",IF(E42>0,"🔄 練習中",IF(AND(C42<>"",C42<TODAY()),"🔴 遅れ","⬜ 未着手"))) | H42: =REPT("█",INT(F42*10))&REPT("░",10-INT(F42*10))&" "&TEXT(F42,"0%")
A43: □ | B43: 問題と思わしくないことの区別 | D43: 3 | E43: 0 | F43: =IF(D43=0,0,MIN(E43/D43,1)) | G43: =IF(AND(E43>=D43,D43>0),"✅ 合格",IF(E43>0,"🔄 練習中",IF(AND(C43<>"",C43<TODAY()),"🔴 遅れ","⬜ 未着手"))) | H43: =REPT("█",INT(F43*10))&REPT("░",10-INT(F43*10))&" "&TEXT(F43,"0%")
A44: □ | B44: 方針方法の区別 | D44: 3 | E44: 0 | F44: =IF(D44=0,0,MIN(E44/D44,1)) | G44: =IF(AND(E44>=D44,D44>0),"✅ 合格",IF(E44>0,"🔄 練習中",IF(AND(C44<>"",C44<TODAY()),"🔴 遅れ","⬜ 未着手"))) | H44: =REPT("█",INT(F44*10))&REPT("░",10-INT(F44*10))&" "&TEXT(F44,"0%")
...

Sheet メンバー2
A1: 🎓 第2弾：初成約〜1ヶ月 トレーニングシート
A2: 👤 メンバー名 | B2: メンバー2 | C2: 📅 開始日 | E2: 📊 全体進捗 | F2: =AVERAGE(F8:F12,F16:F26,F30:F34,F38:F45,F49) | G2: ⏱ 経過日数 | H2: =IF(D2="","",TODAY()-D2) | I2: 日
A3: =REPT("█",INT(F2*30))&REPT("░",30-INT(F2*30))&" "&TEXT(F2,"0%")&" 完了"
A5: ✔ | B5: トレーニング項目 | C5: 目標日 | D5: RP目標 | E5: RP実績 | F5: 達成率 | G5: ステータス | H5: 進捗バー | I5: メモ
A6: 🎯 アポの解像度を上げるトレーニング
B7: 項目名 | C7: 目標日 | D7: RP目標 | E7: RP実績 | F7: 達成率 | G7: ステータス | H7: 進捗バー | I7: メモ
A8: □ | B8: アイスブレイク | D8: 5 | E8: 0 | F8: =IF(D8=0,0,MIN(E8/D8,1)) | G8: =IF(AND(E8>=D8,D8>0),"✅ 合格",IF(E8>0,"🔄 練習中",IF(AND(C8<>"",C8<TODAY()),"🔴 遅れ","⬜ 未着手"))) | H8: =REPT("█",INT(F8*10))&REPT("░",10-INT(F8*10))&" "&TEXT(F8,"0%")
A9: □ | B9: ヒアリング | D9: 5 | E9: 0 | F9: =IF(D9=0,0,MIN(E9/D9,1)) | G9: =IF(AND(E9>=D9,D9>0),"✅ 合格",IF(E9>0,"🔄 練習中",IF(AND(C9<>"",C9<TODAY()),"🔴 遅れ","⬜ 未着手"))) | H9: =REPT("█",INT(F9*10))&REPT("░",10-INT(F9*10))&" "&TEXT(F9,"0%")
A10: □ | B10: ストーリー | D10: 5 | E10: 0 | F10: =IF(D10=0,0,MIN(E10/D10,1)) | G10: =IF(AND(E10>=D10,D10>0),"✅ 合格",IF(E10>0,"🔄 練習中",IF(AND(C10<>"",C10<TODAY()),"🔴 遅れ","⬜ 未着手"))) | H10: =REPT("█",INT(F10*10))&REPT("░",10-INT(F10*10))&" "&TEXT(F10,"0%")
A11: □ | B11: 提案資料 | D11: 3 | E11: 0 | F11: =IF(D11=0,0,MIN(E11/D11,1)) | G11: =IF(AND(E11>=D11,D11>0),"✅ 合格",IF(E11>0,"🔄 練習中",IF(AND(C11<>"",C11<TODAY()),"🔴 遅れ","⬜ 未着手"))) | H11: =REPT("█",INT(F11*10))&REPT("░",10-INT(F11*10))&" "&TEXT(F11,"0%")
A12: □ | B12: ブリッジ | D12: 5 | E12: 0 | F12: =IF(D12=0,0,MIN(E12/D12,1)) | G12: =IF(AND(E12>=D12,D12>0),"✅ 合格",IF(E12>0,"🔄 練習中",IF(AND(C12<>"",C12<TODAY()),"🔴 遅れ","⬜ 未着手"))) | H12: =REPT("█",INT(F12*10))&REPT("░",10-INT(F12*10))&" "&TEXT(F12,"0%")
A14: 🎤 プレの解像度を上げるトレーニング
B15: 項目名 | C15: 目標日 | D15: RP目標 | E15: RP実績 | F15: 達成率 | G15: ステータス | H15: 進捗バー | I15: メモ
A16: □ | B16: 再アイスブレイク | D16: 5 | E16: 0 | F16: =IF(D16=0,0,MIN(E16/D16,1)) | G16: =IF(AND(E16>=D16,D16>0),"✅ 合格",IF(E16>0,"🔄 練習中",IF(AND(C16<>"",C16<TODAY()),"🔴 遅れ","⬜ 未着手"))) | H16: =REPT("█",INT(F16*10))&REPT("░",10-INT(F16*10))&" "&TEXT(F16,"0%")
A17: □ | B17: 再ヒアリング | D17: 5 | E17: 0 | F17: =IF(D17=0,0,MIN(E17/D17,1)) | G17: =IF(AND(E17>=D17,D17>0),"✅ 合格",IF(E17>0,"🔄 練習中",IF(AND(C17<>"",C17<TODAY()),"🔴 遅れ","⬜ 未着手"))) | H17: =REPT("█",INT(F17*10))&REPT("░",10-INT(F17*10))&" "&TEXT(F17,"0%")
A18: □ | B18: 前回の振り返り | D18: 3 | E18: 0 | F18: =IF(D18=0,0,MIN(E18/D18,1)) | G18: =IF(AND(E18>=D18,D18>0),"✅ 合格",IF(E18>0,"🔄 練習中",IF(AND(C18<>"",C18<TODAY()),"🔴 遅れ","⬜ 未着手"))) | H18: =REPT("█",INT(F18*10))&REPT("░",10-INT(F18*10))&" "&TEXT(F18,"0%")
A19: □ | B19: 不安ヒアリング・検討潰し | D19: 8 | E19: 0 | F19: =IF(D19=0,0,MIN(E19/D19,1)) | G19: =IF(AND(E19>=D19,D19>0),"✅ 合格",IF(E19>0,"🔄 練習中",IF(AND(C19<>"",C19<TODAY()),"🔴 遅れ","⬜ 未着手"))) | H19: =REPT("█",INT(F19*10))&REPT("░",10-INT(F19*10))&" "&TEXT(F19,"0%")
A20: □ | B20: サポート説明 | D20: 5 | E20: 0 | F20: =IF(D20=0,0,MIN(E20/D20,1)) | G20: =IF(AND(E20>=D20,D20>0),"✅ 合格",IF(E20>0,"🔄 練習中",IF(AND(C20<>"",C20<TODAY()),"🔴 遅れ","⬜ 未着手"))) | H20: =REPT("█",INT(F20*10))&REPT("░",10-INT(F20*10))&" "&TEXT(F20,"0%")
A21: □ | B21: 卒業生の話 | D21: 5 | E21: 0 | F21: =IF(D21=0,0,MIN(E21/D21,1)) | G21: =IF(AND(E21>=D21,D21>0),"✅ 合格",IF(E21>0,"🔄 練習中",IF(AND(C21<>"",C21<TODAY()),"🔴 遅れ","⬜ 未着手"))) | H21: =REPT("█",INT(F21*10))&REPT("░",10-INT(F21*10))&" "&TEXT(F21,"0%")
A22: □ | B22: アンカリング | D22: 5 | E22: 0 | F22: =IF(D22=0,0,MIN(E22/D22,1)) | G22: =IF(AND(E22>=D22,D22>0),"✅ 合格",IF(E22>0,"🔄 練習中",IF(AND(C22<>"",C22<TODAY()),"🔴 遅れ","⬜ 未着手"))) | H22: =REPT("█",INT(F22*10))&REPT("░",10-INT(F22*10))&" "&TEXT(F22,"0%")
A23: □ | B23: 金額オファー | D23: 8 | E23: 0 | F23: =IF(D23=0,0,MIN(E23/D23,1)) | G23: =IF(AND(E23>=D23,D23>0),"✅ 合格",IF(E23>0,"🔄 練習中",IF(AND(C23<>"",C23<TODAY()),"🔴 遅れ","⬜ 未着手"))) | H23: =REPT("█",INT(F23*10))&REPT("░",10-INT(F23*10))&" "&TEXT(F23,"0%")
A24: □ | B24: 言質後トーク | D24: 5 | E24: 0 | F24: =IF(D24=0,0,MIN(E24/D24,1)) | G24: =IF(AND(E24>=D24,D24>0),"✅ 合格",IF(E24>0,"🔄 練習中",IF(AND(C24<>"",C24<TODAY()),"🔴 遅れ","⬜ 未着手"))) | H24: =REPT("█",INT(F24*10))&REPT("░",10-INT(F24*10))&" "&TEXT(F24,"0%")
A25: □ | B25: 切り返し | D25: 10 | E25: 0 | F25: =IF(D25=0,0,MIN(E25/D25,1)) | G25: =IF(AND(E25>=D25,D25>0),"✅ 合格",IF(E25>0,"🔄 練習中",IF(AND(C25<>"",C25<TODAY()),"🔴 遅れ","⬜ 未着手"))) | H25: =REPT("█",INT(F25*10))&REPT("░",10-INT(F25*10))&" "&TEXT(F25,"0%")
A26: □ | B26: ボイチェン提案 | D26: 5 | E26: 0 | F26: =IF(D26=0,0,MIN(E26/D26,1)) | G26: =IF(AND(E26>=D26,D26>0),"✅ 合格",IF(E26>0,"🔄 練習中",IF(AND(C26<>"",C26<TODAY()),"🔴 遅れ","⬜ 未着手"))) | H26: =REPT("█",INT(F26*10))&REPT("░",10-INT(F26*10))&" "&TEXT(F26,"0%")
A28: 💬 渋りトーク
B29: 項目名 | C29: 目標日 | D29: RP目標 | E29: RP実績 | F29: 達成率 | G29: ステータス | H29: 進捗バー | I29: メモ
A30: □ | B30: 金額渋りトーク | D30: 8 | E30: 0 | F30: =IF(D30=0,0,MIN(E30/D30,1)) | G30: =IF(AND(E30>=D30,D30>0),"✅ 合格",IF(E30>0,"🔄 練習中",IF(AND(C30<>"",C30<TODAY()),"🔴 遅れ","⬜ 未着手"))) | H30: =REPT("█",INT(F30*10))&REPT("░",10-INT(F30*10))&" "&TEXT(F30,"0%")
A31: □ | B31: 相談渋りのトーク | D31: 8 | E31: 0 | F31: =IF(D31=0,0,MIN(E31/D31,1)) | G31: =IF(AND(E31>=D31,D31>0),"✅ 合格",IF(E31>0,"🔄 練習中",IF(AND(C31<>"",C31<TODAY()),"🔴 遅れ","⬜ 未着手"))) | H31: =REPT("█",INT(F31*10))&REPT("░",10-INT(F31*10))&" "&TEXT(F31,"0%")
A32: □ | B32: 他社比較渋りトーク | D32: 5 | E32: 0 | F32: =IF(D32=0,0,MIN(E32/D32,1)) | G32: =IF(AND(E32>=D32,D32>0),"✅ 合格",IF(E32>0,"🔄 練習中",IF(AND(C32<>"",C32<TODAY()),"🔴 遅れ","⬜ 未着手"))) | H32: =REPT("█",INT(F32*10))&REPT("░",10-INT(F32*10))&" "&TEXT(F32,"0%")
A33: □ | B33: 自信ない渋りトーク | D33: 5 | E33: 0 | F33: =IF(D33=0,0,MIN(E33/D33,1)) | G33: =IF(AND(E33>=D33,D33>0),"✅ 合格",IF(E33>0,"🔄 練習中",IF(AND(C33<>"",C33<TODAY()),"🔴 遅れ","⬜ 未着手"))) | H33: =REPT("█",INT(F33*10))&REPT("░",10-INT(F33*10))&" "&TEXT(F33,"0%")
A34: □ | B34: 今じゃない渋りトーク | D34: 5 | E34: 0 | F34: =IF(D34=0,0,MIN(E34/D34,1)) | G34: =IF(AND(E34>=D34,D34>0),"✅ 合格",IF(E34>0,"🔄 練習中",IF(AND(C34<>"",C34<TODAY()),"🔴 遅れ","⬜ 未着手"))) | H34: =REPT("█",INT(F34*10))&REPT("░",10-INT(F34*10))&" "&TEXT(F34,"0%")
A36: ⚡ スキル強化
B37: 項目名 | C37: 目標日 | D37: RP目標 | E37: RP実績 | F37: 達成率 | G37: ステータス | H37: 進捗バー | I37: メモ
A38: □ | B38: アポやプレでの時間配分の徹底 | D38: 3 | E38: 0 | F38: =IF(D38=0,0,MIN(E38/D38,1)) | G38: =IF(AND(E38>=D38,D38>0),"✅ 合格",IF(E38>0,"🔄 練習中",IF(AND(C38<>"",C38<TODAY()),"🔴 遅れ","⬜ 未着手"))) | H38: =REPT("█",INT(F38*10))&REPT("░",10-INT(F38*10))&" "&TEXT(F38,"0%")
A39: □ | B39: ボイチェン提案 | D39: 3 | E39: 0 | F39: =IF(D39=0,0,MIN(E39/D39,1)) | G39: =IF(AND(E39>=D39,D39>0),"✅ 合格",IF(E39>0,"🔄 練習中",IF(AND(C39<>"",C39<TODAY()),"🔴 遅れ","⬜ 未着手"))) | H39: =REPT("█",INT(F39*10))&REPT("░",10-INT(F39*10))&" "&TEXT(F39,"0%")
A40: □ | B40: 不安ヒアリング | D40: 5 | E40: 0 | F40: =IF(D40=0,0,MIN(E40/D40,1)) | G40: =IF(AND(E40>=D40,D40>0),"✅ 合格",IF(E40>0,"🔄 練習中",IF(AND(C40<>"",C40<TODAY()),"🔴 遅れ","⬜ 未着手"))) | H40: =REPT("█",INT(F40*10))&REPT("░",10-INT(F40*10))&" "&TEXT(F40,"0%")
A41: □ | B41: 資金繰りの解像度UP（カードの分割・最低限の金融リテラシー） | D41: 3 | E41: 0 | F41: =IF(D41=0,0,MIN(E41/D41,1)) | G41: =IF(AND(E41>=D41,D41>0),"✅ 合格",IF(E41>0,"🔄 練習中",IF(AND(C41<>"",C41<TODAY()),"🔴 遅れ","⬜ 未着手"))) | H41: =REPT("█",INT(F41*10))&REPT("░",10-INT(F41*10))&" "&TEXT(F41,"0%")
A42: □ | B42: 事実解釈の区別 | D42: 3 | E42: 0 | F42: =IF(D42=0,0,MIN(E42/D42,1)) | G42: =IF(AND(E42>=D42,D42>0),"✅ 合格",IF(E42>0,"🔄 練習中",IF(AND(C42<>"",C42<TODAY()),"🔴 遅れ","⬜ 未着手"))) | H42: =REPT("█",INT(F42*10))&REPT("░",10-INT(F42*10))&" "&TEXT(F42,"0%")
A43: □ | B43: 問題と思わしくないことの区別 | D43: 3 | E43: 0 | F43: =IF(D43=0,0,MIN(E43/D43,1)) | G43: =IF(AND(E43>=D43,D43>0),"✅ 合格",IF(E43>0,"🔄 練習中",IF(AND(C43<>"",C43<TODAY()),"🔴 遅れ","⬜ 未着手"))) | H43: =REPT("█",INT(F43*10))&REPT("░",10-INT(F43*10))&" "&TEXT(F43,"0%")
A44: □ | B44: 方針方法の区別 | D44: 3 | E44: 0 | F44: =IF(D44=0,0,MIN(E44/D44,1)) | G44: =IF(AND(E44>=D44,D44>0),"✅ 合格",IF(E44>0,"🔄 練習中",IF(AND(C44<>"",C44<TODAY()),"🔴 遅れ","⬜ 未着手"))) | H44: =REPT("█",INT(F44*10))&REPT("░",10-INT(F44*10))&" "&TEXT(F44,"0%")
...

Sheet メンバー3
A1: 🎓 第2弾：初成約〜1ヶ月 トレーニングシート
A2: 👤 メンバー名 | B2: メンバー3 | C2: 📅 開始日 | E2: 📊 全体進捗 | F2: =AVERAGE(F8:F12,F16:F26,F30:F34,F38:F45,F49) | G2: ⏱ 経過日数 | H2: =IF(D2="","",TODAY()-D2) | I2: 日
A3: =REPT("█",INT(F2*30))&REPT("░",30-INT(F2*30))&" "&TEXT(F2,"0%")&" 完了"
A5: ✔ | B5: トレーニング項目 | C5: 目標日 | D5: RP目標 | E5: RP実績 | F5: 達成率 | G5: ステータス | H5: 進捗バー | I5: メモ
A6: 🎯 アポの解像度を上げるトレーニング
B7: 項目名 | C7: 目標日 | D7: RP目標 | E7: RP実績 | F7: 達成率 | G7: ステータス | H7: 進捗バー | I7: メモ
A8: □ | B8: アイスブレイク | D8: 5 | E8: 0 | F8: =IF(D8=0,0,MIN(E8/D8,1)) | G8: =IF(AND(E8>=D8,D8>0),"✅ 合格",IF(E8>0,"🔄 練習中",IF(AND(C8<>"",C8<TODAY()),"🔴 遅れ","⬜ 未着手"))) | H8: =REPT("█",INT(F8*10))&REPT("░",10-INT(F8*10))&" "&TEXT(F8,"0%")
A9: □ | B9: ヒアリング | D9: 5 | E9: 0 | F9: =IF(D9=0,0,MIN(E9/D9,1)) | G9: =IF(AND(E9>=D9,D9>0),"✅ 合格",IF(E9>0,"🔄 練習中",IF(AND(C9<>"",C9<TODAY()),"🔴 遅れ","⬜ 未着手"))) | H9: =REPT("█",INT(F9*10))&REPT("░",10-INT(F9*10))&" "&TEXT(F9,"0%")
A10: □ | B10: ストーリー | D10: 5 | E10: 0 | F10: =IF(D10=0,0,MIN(E10/D10,1)) | G10: =IF(AND(E10>=D10,D10>0),"✅ 合格",IF(E10>0,"🔄 練習中",IF(AND(C10<>"",C10<TODAY()),"🔴 遅れ","⬜ 未着手"))) | H10: =REPT("█",INT(F10*10))&REPT("░",10-INT(F10*10))&" "&TEXT(F10,"0%")
A11: □ | B11: 提案資料 | D11: 3 | E11: 0 | F11: =IF(D11=0,0,MIN(E11/D11,1)) | G11: =IF(AND(E11>=D11,D11>0),"✅ 合格",IF(E11>0,"🔄 練習中",IF(AND(C11<>"",C11<TODAY()),"🔴 遅れ","⬜ 未着手"))) | H11: =REPT("█",INT(F11*10))&REPT("░",10-INT(F11*10))&" "&TEXT(F11,"0%")
A12: □ | B12: ブリッジ | D12: 5 | E12: 0 | F12: =IF(D12=0,0,MIN(E12/D12,1)) | G12: =IF(AND(E12>=D12,D12>0),"✅ 合格",IF(E12>0,"🔄 練習中",IF(AND(C12<>"",C12<TODAY()),"🔴 遅れ","⬜ 未着手"))) | H12: =REPT("█",INT(F12*10))&REPT("░",10-INT(F12*10))&" "&TEXT(F12,"0%")
A14: 🎤 プレの解像度を上げるトレーニング
B15: 項目名 | C15: 目標日 | D15: RP目標 | E15: RP実績 | F15: 達成率 | G15: ステータス | H15: 進捗バー | I15: メモ
A16: □ | B16: 再アイスブレイク | D16: 5 | E16: 0 | F16: =IF(D16=0,0,MIN(E16/D16,1)) | G16: =IF(AND(E16>=D16,D16>0),"✅ 合格",IF(E16>0,"🔄 練習中",IF(AND(C16<>"",C16<TODAY()),"🔴 遅れ","⬜ 未着手"))) | H16: =REPT("█",INT(F16*10))&REPT("░",10-INT(F16*10))&" "&TEXT(F16,"0%")
A17: □ | B17: 再ヒアリング | D17: 5 | E17: 0 | F17: =IF(D17=0,0,MIN(E17/D17,1)) | G17: =IF(AND(E17>=D17,D17>0),"✅ 合格",IF(E17>0,"🔄 練習中",IF(AND(C17<>"",C17<TODAY()),"🔴 遅れ","⬜ 未着手"))) | H17: =REPT("█",INT(F17*10))&REPT("░",10-INT(F17*10))&" "&TEXT(F17,"0%")
A18: □ | B18: 前回の振り返り | D18: 3 | E18: 0 | F18: =IF(D18=0,0,MIN(E18/D18,1)) | G18: =IF(AND(E18>=D18,D18>0),"✅ 合格",IF(E18>0,"🔄 練習中",IF(AND(C18<>"",C18<TODAY()),"🔴 遅れ","⬜ 未着手"))) | H18: =REPT("█",INT(F18*10))&REPT("░",10-INT(F18*10))&" "&TEXT(F18,"0%")
A19: □ | B19: 不安ヒアリング・検討潰し | D19: 8 | E19: 0 | F19: =IF(D19=0,0,MIN(E19/D19,1)) | G19: =IF(AND(E19>=D19,D19>0),"✅ 合格",IF(E19>0,"🔄 練習中",IF(AND(C19<>"",C19<TODAY()),"🔴 遅れ","⬜ 未着手"))) | H19: =REPT("█",INT(F19*10))&REPT("░",10-INT(F19*10))&" "&TEXT(F19,"0%")
A20: □ | B20: サポート説明 | D20: 5 | E20: 0 | F20: =IF(D20=0,0,MIN(E20/D20,1)) | G20: =IF(AND(E20>=D20,D20>0),"✅ 合格",IF(E20>0,"🔄 練習中",IF(AND(C20<>"",C20<TODAY()),"🔴 遅れ","⬜ 未着手"))) | H20: =REPT("█",INT(F20*10))&REPT("░",10-INT(F20*10))&" "&TEXT(F20,"0%")
A21: □ | B21: 卒業生の話 | D21: 5 | E21: 0 | F21: =IF(D21=0,0,MIN(E21/D21,1)) | G21: =IF(AND(E21>=D21,D21>0),"✅ 合格",IF(E21>0,"🔄 練習中",IF(AND(C21<>"",C21<TODAY()),"🔴 遅れ","⬜ 未着手"))) | H21: =REPT("█",INT(F21*10))&REPT("░",10-INT(F21*10))&" "&TEXT(F21,"0%")
A22: □ | B22: アンカリング | D22: 5 | E22: 0 | F22: =IF(D22=0,0,MIN(E22/D22,1)) | G22: =IF(AND(E22>=D22,D22>0),"✅ 合格",IF(E22>0,"🔄 練習中",IF(AND(C22<>"",C22<TODAY()),"🔴 遅れ","⬜ 未着手"))) | H22: =REPT("█",INT(F22*10))&REPT("░",10-INT(F22*10))&" "&TEXT(F22,"0%")
A23: □ | B23: 金額オファー | D23: 8 | E23: 0 | F23: =IF(D23=0,0,MIN(E23/D23,1)) | G23: =IF(AND(E23>=D23,D23>0),"✅ 合格",IF(E23>0,"🔄 練習中",IF(AND(C23<>"",C23<TODAY()),"🔴 遅れ","⬜ 未着手"))) | H23: =REPT("█",INT(F23*10))&REPT("░",10-INT(F23*10))&" "&TEXT(F23,"0%")
A24: □ | B24: 言質後トーク | D24: 5 | E24: 0 | F24: =IF(D24=0,0,MIN(E24/D24,1)) | G24: =IF(AND(E24>=D24,D24>0),"✅ 合格",IF(E24>0,"🔄 練習中",IF(AND(C24<>"",C24<TODAY()),"🔴 遅れ","⬜ 未着手"))) | H24: =REPT("█",INT(F24*10))&REPT("░",10-INT(F24*10))&" "&TEXT(F24,"0%")
A25: □ | B25: 切り返し | D25: 10 | E25: 0 | F25: =IF(D25=0,0,MIN(E25/D25,1)) | G25: =IF(AND(E25>=D25,D25>0),"✅ 合格",IF(E25>0,"🔄 練習中",IF(AND(C25<>"",C25<TODAY()),"🔴 遅れ","⬜ 未着手"))) | H25: =REPT("█",INT(F25*10))&REPT("░",10-INT(F25*10))&" "&TEXT(F25,"0%")
A26: □ | B26: ボイチェン提案 | D26: 5 | E26: 0 | F26: =IF(D26=0,0,MIN(E26/D26,1)) | G26: =IF(AND(E26>=D26,D26>0),"✅ 合格",IF(E26>0,"🔄 練習中",IF(AND(C26<>"",C26<TODAY()),"🔴 遅れ","⬜ 未着手"))) | H26: =REPT("█",INT(F26*10))&REPT("░",10-INT(F26*10))&" "&TEXT(F26,"0%")
A28: 💬 渋りトーク
B29: 項目名 | C29: 目標日 | D29: RP目標 | E29: RP実績 | F29: 達成率 | G29: ステータス | H29: 進捗バー | I29: メモ
A30: □ | B30: 金額渋りトーク | D30: 8 | E30: 0 | F30: =IF(D30=0,0,MIN(E30/D30,1)) | G30: =IF(AND(E30>=D30,D30>0),"✅ 合格",IF(E30>0,"🔄 練習中",IF(AND(C30<>"",C30<TODAY()),"🔴 遅れ","⬜ 未着手"))) | H30: =REPT("█",INT(F30*10))&REPT("░",10-INT(F30*10))&" "&TEXT(F30,"0%")
A31: □ | B31: 相談渋りのトーク | D31: 8 | E31: 0 | F31: =IF(D31=0,0,MIN(E31/D31,1)) | G31: =IF(AND(E31>=D31,D31>0),"✅ 合格",IF(E31>0,"🔄 練習中",IF(AND(C31<>"",C31<TODAY()),"🔴 遅れ","⬜ 未着手"))) | H31: =REPT("█",INT(F31*10))&REPT("░",10-INT(F31*10))&" "&TEXT(F31,"0%")
A32: □ | B32: 他社比較渋りトーク | D32: 5 | E32: 0 | F32: =IF(D32=0,0,MIN(E32/D32,1)) | G32: =IF(AND(E32>=D32,D32>0),"✅ 合格",IF(E32>0,"🔄 練習中",IF(AND(C32<>"",C32<TODAY()),"🔴 遅れ","⬜ 未着手"))) | H32: =REPT("█",INT(F32*10))&REPT("░",10-INT(F32*10))&" "&TEXT(F32,"0%")
A33: □ | B33: 自信ない渋りトーク | D33: 5 | E33: 0 | F33: =IF(D33=0,0,MIN(E33/D33,1)) | G33: =IF(AND(E33>=D33,D33>0),"✅ 合格",IF(E33>0,"🔄 練習中",IF(AND(C33<>"",C33<TODAY()),"🔴 遅れ","⬜ 未着手"))) | H33: =REPT("█",INT(F33*10))&REPT("░",10-INT(F33*10))&" "&TEXT(F33,"0%")
A34: □ | B34: 今じゃない渋りトーク | D34: 5 | E34: 0 | F34: =IF(D34=0,0,MIN(E34/D34,1)) | G34: =IF(AND(E34>=D34,D34>0),"✅ 合格",IF(E34>0,"🔄 練習中",IF(AND(C34<>"",C34<TODAY()),"🔴 遅れ","⬜ 未着手"))) | H34: =REPT("█",INT(F34*10))&REPT("░",10-INT(F34*10))&" "&TEXT(F34,"0%")
A36: ⚡ スキル強化
B37: 項目名 | C37: 目標日 | D37: RP目標 | E37: RP実績 | F37: 達成率 | G37: ステータス | H37: 進捗バー | I37: メモ
A38: □ | B38: アポやプレでの時間配分の徹底 | D38: 3 | E38: 0 | F38: =IF(D38=0,0,MIN(E38/D38,1)) | G38: =IF(AND(E38>=D38,D38>0),"✅ 合格",IF(E38>0,"🔄 練習中",IF(AND(C38<>"",C38<TODAY()),"🔴 遅れ","⬜ 未着手"))) | H38: =REPT("█",INT(F38*10))&REPT("░",10-INT(F38*10))&" "&TEXT(F38,"0%")
A39: □ | B39: ボイチェン提案 | D39: 3 | E39: 0 | F39: =IF(D39=0,0,MIN(E39/D39,1)) | G39: =IF(AND(E39>=D39,D39>0),"✅ 合格",IF(E39>0,"🔄 練習中",IF(AND(C39<>"",C39<TODAY()),"🔴 遅れ","⬜ 未着手"))) | H39: =REPT("█",INT(F39*10))&REPT("░",10-INT(F39*10))&" "&TEXT(F39,"0%")
A40: □ | B40: 不安ヒアリング | D40: 5 | E40: 0 | F40: =IF(D40=0,0,MIN(E40/D40,1)) | G40: =IF(AND(E40>=D40,D40>0),"✅ 合格",IF(E40>0,"🔄 練習中",IF(AND(C40<>"",C40<TODAY()),"🔴 遅れ","⬜ 未着手"))) | H40: =REPT("█",INT(F40*10))&REPT("░",10-INT(F40*10))&" "&TEXT(F40,"0%")
A41: □ | B41: 資金繰りの解像度UP（カードの分割・最低限の金融リテラシー） | D41: 3 | E41: 0 | F41: =IF(D41=0,0,MIN(E41/D41,1)) | G41: =IF(AND(E41>=D41,D41>0),"✅ 合格",IF(E41>0,"🔄 練習中",IF(AND(C41<>"",C41<TODAY()),"🔴 遅れ","⬜ 未着手"))) | H41: =REPT("█",INT(F41*10))&REPT("░",10-INT(F41*10))&" "&TEXT(F41,"0%")
A42: □ | B42: 事実解釈の区別 | D42: 3 | E42: 0 | F42: =IF(D42=0,0,MIN(E42/D42,1)) | G42: =IF(AND(E42>=D42,D42>0),"✅ 合格",IF(E42>0,"🔄 練習中",IF(AND(C42<>"",C42<TODAY()),"🔴 遅れ","⬜ 未着手"))) | H42: =REPT("█",INT(F42*10))&REPT("░",10-INT(F42*10))&" "&TEXT(F42,"0%")
A43: □ | B43: 問題と思わしくないことの区別 | D43: 3 | E43: 0 | F43: =IF(D43=0,0,MIN(E43/D43,1)) | G43: =IF(AND(E43>=D43,D43>0),"✅ 合格",IF(E43>0,"🔄 練習中",IF(AND(C43<>"",C43<TODAY()),"🔴 遅れ","⬜ 未着手"))) | H43: =REPT("█",INT(F43*10))&REPT("░",10-INT(F43*10))&" "&TEXT(F43,"0%")
A44: □ | B44: 方針方法の区別 | D44: 3 | E44: 0 | F44: =IF(D44=0,0,MIN(E44/D44,1)) | G44: =IF(AND(E44>=D44,D44>0),"✅ 合格",IF(E44>0,"🔄 練習中",IF(AND(C44<>"",C44<TODAY()),"🔴 遅れ","⬜ 未着手"))) | H44: =REPT("█",INT(F44*10))&REPT("░",10-INT(F44*10))&" "&TEXT(F44,"0%")
...
